Workbook
Name budyn: '[1]Data'!$D$3:$D$4
Name Start_Year: '[2]Main'!$C$9
Name stream: '[1]Data'!$B$3:$B$11
Name years: '[1]Data'!$F$3:$F$10

Sheet Datos
G3: Datos
C8: Resumen Ejecutivo NUEVO LOCAL
J9: Nueva Tienda | K9: Reubicaciones
C10: Fecha | E10: 46132 | H10: Tasas de Rendimiento | I10: TIR | J10: =IRR('Resumen business case'!D37:I37) -> 0.47176987
C11: Comuna | E11: Vitacura | I11: VAN | J11: =NPV(E30,'Resumen business case'!D37:I37) -> 331.5608
C12: Ubicación | E12: Americo Vespucio 2515
C13: Tipo | E13: Autoplanet
B14: 500 | C14: Superficie Local | D14: mt2 | E14: =B14 -> 500
B15: 0.375 | C15: Valor x mt2 | D15: mt2 | E15: =B15 -> 0.375 | F15: 2 meses de gracia
B16: 10 | C16: Contrato Arriendo | D16: Años | E16: =B16 -> 10 | F16: Renovable 5 años. Clausula salida desde mes 36
C17: Canon | D17: UF | E17: =+E14*E15 -> 187.5
B18: 0 | C18: Gasto comun | D18: UF | E18: =E14*B18 -> 0
C19: Inicio | E19: 46236
C20: Periodo Gracia / Habilitación | D20: meses | E20: 2
B21: =(12-MONTH(Datos!E19))-1 | C21: Inicio pago Canon | E21: =E19+(31*2) -> 46298
C22: Fecha estimada de Finalización | E22: =E19+(365*E16) -> 49886
B23: 125 | C23: Inversión Habilitacion | D23: $ Clp | E23: =B23*1000000 -> 125000000
B24: 30 | C24: Mobiliario AF | D24: $ Clp | E24: =B24*1000000 -> 30000000
B25: 100 | C25: Inversion Inventario | D25: $ Clp | E25: =B25*1000000 -> 100000000
B26: 10 | C26: Inversion Tecnologia | D26: $ Clp | E26: =B26*1000000 -> 10000000
B27: 0 | C27: Inversion Marketing | D27: $ Clp | E27: =B27*1000000 -> 0
C28: Garantia | D28: UF | E28: =E17 -> 187.5
C29: Cobro por Instalaciones | D29: UF | E29: 0
C30: Tasa de descuento | E30: 0.12
C31: Periodo de Recuperación (Año) | D31: años | E31: =+'Resumen business case'!D39 -> 3 | N31: año 2032
C32: Rentabilidad al 4 año | E32: =+'Resumen business case'!H44 -> 0.2256685 | N32: =$I$27 -> 0
C33: TIR | E33: =J10 -> 0.47176987
C34: VAN | E34: =+J11 -> 331.5608
C37: Resumen Comercial (Negociación avanzada)
C39: Tipo de Operación | D39: Arriendo de caja
C40: Datos de Operador | D40: Juan Martinez (inversionista local)
C41: Superficie Local | D41: 547
C42: Superficie Total | D42: 500 mt2
C43: Ubicación | D43: =E12 -> Americo Vespucio 2515
C44: Estacionamientos | D44: Sí, 6 autos + espacio de exhibicion
C45: Visibilidad | D45: Alta. Es buena desde avenida
C46: Accesibilidad | D46: Alta. Comodo para carga y descarga
C47: Estado Actual | D47: Construído 300 mt2 en 1 planta que usariamos como Showroom y bodega de implementos y repuesto spesados. Segundo nivel: servicios a colaboradores y bodega elementos pequeños.
C48: Plazo de arriendo | D48: 10 años
C49: Fecha entrega local estimada | D49: =E19 -> 46236
...

Sheet Resumen business case
C7: Año | D7: 0 | E7: 1 | F7: 2 | G7: 3 | H7: 4 | I7: 5 | L7: Ingresos
D8: 2025 | E8: 2026 | F8: 2027 | G8: 2028 | H8: 2029 | I8: 2030 | L8: Año | M8: 2025 | N8: 2026 | O8: 2027 | P8: 2028 | Q8: 2029 | R8: 2030
C9: Venta / mes | E9: =N10 -> 60 | F9: =O10 -> 80 | G9: =P10 -> 90 | H9: =Q10 -> 95 | I9: =R10 -> 99.75 | J9: Corregido | L9: Ventas (CLP) | M9: 0 | N9: =+(N10*1000000*Datos!B21) -> 180000000 | O9: =+(O10*1000000*12) -> 960000000 | P9: =+(P10*1000000*12) -> 1080000000 | Q9: =+(Q10*1000000*12) -> 1140000000 | R9: =+Q9*1.05 -> 1197000000 | S9: Corregido
C10: Ingresos | E10: =N9/1000000 -> 180 | F10: =O9/1000000 -> 960 | G10: =P9/1000000 -> 1080 | H10: =Q9/1000000 -> 1140 | I10: =R9/1000000 -> 1197 | L10: Ventas (CLP)/mes | N10: 60 | O10: 80 | P10: 90 | Q10: 95 | R10: =Q10*1.05 -> 99.75 | S10: Corregido
C11: Costo por ventas | E11: =N13/1000000 -> -84.6 | F11: =O13/1000000 -> -451.2 | G11: =P13/1000000 -> -507.6 | H11: =Q13/1000000 -> -535.8 | I11: =R13/1000000 -> -562.59 | L11: Costos por ventas
C12: Margen directo % | E12: =+IFERROR(((E10+E11)/E10),0) -> 0.53 | F12: =+IFERROR(((F10+F11)/F10),0) -> 0.53 | G12: =+IFERROR(((G10+G11)/G10),0) -> 0.53 | H12: =+IFERROR(((H10+H11)/H10),0) -> 0.53 | I12: =+IFERROR(((I10+I11)/I10),0) -> 0.53 | L12: Año | M12: 2025 | N12: 2026 | O12: 2027 | P12: 2028 | Q12: 2029 | R12: 2030
C13: Otros Costos directos | E13: =+E$10*N15 -> -0.54 | F13: =+F$10*O15 -> -2.88 | G13: =+G$10*P15 -> -3.24 | H13: =+H$10*Q15 -> -3.42 | I13: =+I$10*R15 -> -3.591 | L13: Costos Directos | M13: =(+M9*M14)-M9 -> 0 | N13: =(+N9*N14)-N9 -> -84600000 | O13: =(+O9*O14)-O9 -> -451200000 | P13: =(+P9*P14)-P9 -> -507600000 | Q13: =(+Q9*Q14)-Q9 -> -535800000 | R13: =(+R9*R14)-R9 -> -562590000
C14: Costos Variables | E14: =+E$10*N16 -> -9 | F14: =+F$10*O16 -> -48 | G14: =+G$10*P16 -> -54 | H14: =+H$10*Q16 -> -57 | I14: =+I$10*R16 -> -59.85 | L14: Margen% | N14: 0.53 | O14: =N14 -> 0.53 | P14: =O14 -> 0.53 | Q14: =P14 -> 0.53 | R14: =Q14 -> 0.53
C15: Margen de contribucion $ | E15: =+E10+E11+E13+E14 -> 85.86 | F15: =+F10+F11+F13+F14 -> 457.92 | G15: =+G10+G11+G13+G14 -> 515.16 | H15: =+H10+H11+H13+H14 -> 543.78 | I15: =+I10+I11+I13+I14 -> 570.969 | L15: Otros Costos directos | M15: =+M9*-7% -> 0 | N15: -0.003 | O15: =N15 -> -0.003 | P15: =O15 -> -0.003 | Q15: =P15 -> -0.003 | R15: =Q15 -> -0.003
A16: Año 1 | C16: Margen de contribucion % | E16: =+IFERROR((E15/E10),0) -> 0.477 | F16: =+IFERROR((F15/F10),0) -> 0.477 | G16: =+IFERROR((G15/G10),0) -> 0.477 | H16: =+IFERROR((H15/H10),0) -> 0.477 | I16: =+IFERROR((I15/I10),0) -> 0.477 | L16: Costos Variales | M16: =+M9*-20% -> 0 | N16: -0.05 | O16: -0.05 | P16: -0.05 | Q16: -0.05 | R16: -0.05
A17: =Datos!B21+1 -> 4 | B17: 6.5 | C17: Gastos Personal | E17: =-B17*(A17) -> -26 | F17: =(-B17*12)*1.032 -> -80.496 | G17: =+F17*1.032 -> -83.071872 | H17: =+G17*1.032 -> -85.730172 | I17: =+H17*1.032 -> -88.473537 | J17: Corregido
C18: Publicidad y Promocion | E18: 0 | F18: =+E18*1.032 -> 0 | G18: =+F18*1.032 -> 0 | H18: =+G18*1.032 -> 0 | I18: =+H18*1.032 -> 0 | L18: Capital empleado
C19: Gastos Generales | E19: =-0.8*(MONTH(Datos!B21)) -> -0.8 | F19: =-0.8*12*1.032 -> -9.9072 | G19: =+F19*1.032 -> -10.22423 | H19: =+G19*1.032 -> -10.551406 | I19: =+H19*1.032 -> -10.889051 | L19: Año | M19: 2025 | N19: 2026 | O19: 2027 | P19: 2028 | Q19: 2029 | R19: 2030
C20: Tecnologia | E20: =+E$10*N30 -> -3.24 | F20: =+F$10*O30 -> -17.28 | G20: =+G$10*P30 -> -19.44 | H20: =+H$10*Q30 -> -20.52 | I20: =+I$10*R30 -> -21.546 | L20: CXP | M20: =+M13 -> 0 | N20: 0 | O20: 0 | P20: 0 | Q20: 0 | R20: 0
C21: Ocupacion (sin Arrdo) | E21: =+E$10*N31 -> -2.304 | F21: =+F$10*O31 -> -12.288 | G21: =+G$10*P31 -> -13.824 | H21: =+H$10*Q31 -> -14.592 | I21: =+I$10*R31 -> -15.3216 | L21: CXC | N21: 0 | O21: 0 | P21: 0 | Q21: 0 | R21: 0
C22: Canon Arriendo | E22: =-((Datos!$E$17*Supuestos!C3)/1000000)*Datos!B21 -> -22.965841 | F22: =-((Datos!$E$17*Supuestos!D$3)*12)/1000000 -> -94.986719 | G22: =-(((Datos!$E$17+1.05)*Supuestos!E$3)*12)/1000000 -> -98.766279 | H22: =-(((Datos!$E$17+1.05)*Supuestos!F$3)*12)/1000000 -> -102.12433 | I22: =-(((Datos!$E$17+1.1)*Supuestos!G$3)*12)/1000000 -> -105.62456 | J22: Corregido | L22: Inventario | N22: 100000000 | O22: =N22 -> 100000000 | P22: =O22 -> 100000000 | Q22: =P22 -> 100000000 | R22: =Q22 -> 100000000
C23: Gasto comun | E23: =-((Datos!$E$18*Supuestos!C$3)*$A$17)/1000000 -> 0 | F23: =-((Datos!$E$18*Supuestos!D$3)*12)/1000000 -> 0 | G23: =-((Datos!$E$18*Supuestos!E$3)*12)/1000000 -> 0 | H23: =-((Datos!$E$18*Supuestos!F$3)*12)/1000000 -> 0 | I23: =-((Datos!$E$18*Supuestos!G$3)*12)/1000000 -> 0 | J23: Corregido | L23: Total Capital empleado | M23: =SUM(M20:M22) -> 0 | N23: =SUM(N20:N22) -> 100000000 | O23: =SUM(O20:O22) -> 100000000 | P23: =SUM(P20:P22) -> 100000000 | Q23: =SUM(Q20:Q22) -> 100000000 | R23: =SUM(R20:R22) -> 100000000
C24: GAVs | E24: =+SUM(E17:E23) -> -55.309841 | F24: =+SUM(F17:F23) -> -214.95792 | G24: =+SUM(G17:G23) -> -225.32638 | H24: =+SUM(H17:H23) -> -233.51791 | I24: =+SUM(I17:I23) -> -241.85475
C25: EBITDA | E25: =+E15+E24 -> 30.550159 | F25: =+F15+F24 -> 242.96208 | G25: =+G15+G24 -> 289.83362 | H25: =+H15+H24 -> 310.26209 | I25: =+I15+I24 -> 329.11425 | L25: Gastos generales
C26: Ebitda/vta | E26: =E25/E10 -> 0.1697231 | F26: =F25/F10 -> 0.2530855 | G26: =G25/G10 -> 0.26836446 | H26: =H25/H10 -> 0.27215973 | I26: =I25/I10 -> 0.27494925 | J26: Corregido | L26: Año | M26: 2025 | N26: 2026 | O26: 2027 | P26: 2028 | Q26: 2029 | R26: 2030
C27: Depreciación y Amortizacion | E27: =+N35 -> -53 | F27: =+O35 -> -53 | G27: =+P35 -> -53 | H27: =+Q35 -> -53 | I27: =+R35 -> -53 | L27: Gastos Personal | N27: =+E17/E10 -> -0.14444444 | O27: =+F17/F10 -> -0.08385 | P27: =+G17/G10 -> -0.0769184 | Q27: =+H17/H10 -> -0.075201905 | R27: =+I17/I10 -> -0.07391273
C28: EBIT | E28: =+E25+E27 -> -22.449841 | F28: =+F25+F27 -> 189.96208 | G28: =+G25+G27 -> 236.83362 | H28: =+H25+H27 -> 257.26209 | I28: =+I25+I27 -> 276.11425 | L28: Publicidad y Promocion | N28: =+E18/E10 -> 0 | O28: =+F18/F10 -> 0 | P28: =+G18/G10 -> 0 | Q28: =+H18/H10 -> 0 | R28: =+I18/I10 -> 0
C29: ROS% | E29: =+IFERROR((E28/E$10),0) -> -0.12472134 | F29: =+IFERROR((F28/F$10),0) -> 0.19787717 | G29: =+IFERROR((G28/G$10),0) -> 0.21929039 | H29: =+IFERROR((H28/H$10),0) -> 0.2256685 | I29: =+IFERROR((I28/I$10),0) -> 0.23067189 | L29: Gastos Generales | N29: =+E19/E10 -> -0.0044444444 | O29: =+F19/F10 -> -0.01032 | P29: =+G19/G10 -> -0.00946688 | Q29: =+H19/H10 -> -0.0092556191 | R29: =+I19/I10 -> -0.0090969513
C30: Intereses (-) | E30: =+E$10*N36 -> 0 | F30: =+F$10*O36 -> 0 | G30: =+G$10*P36 -> 0 | H30: =+H$10*Q36 -> 0 | I30: =+I$10*R36 -> 0 | L30: Tecnologia | N30: -0.018 | O30: -0.018 | P30: -0.018 | Q30: -0.018 | R30: -0.018
C31: UAI | E31: =+E28+E30 -> -22.449841 | F31: =+F28+F30 -> 189.96208 | G31: =+G28+G30 -> 236.83362 | H31: =+H28+H30 -> 257.26209 | I31: =+I28+I30 -> 276.11425 | L31: =C21 -> Ocupacion (sin Arrdo) | N31: -0.0128 | O31: -0.0128 | P31: -0.0128 | Q31: -0.0128 | R31: -0.0128
C32: Impuesto% | E32: =N38 -> 0.27 | F32: =O38 -> 0.27 | G32: =P38 -> 0.27 | H32: =Q38 -> 0.27 | I32: =R38 -> 0.27
C33: Impuesto | E33: =E31*-E32 -> 6.0614571 | F33: =F31*-F32 -> -51.289762 | G33: =G31*-G32 -> -63.945077 | H33: =H31*-H32 -> -69.460764 | I33: =I31*-I32 -> -74.550848 | L33: Análisis Financiero
C34: UDI | E34: =+E31+E33 -> -16.388384 | F34: =+F31+F33 -> 138.67232 | G34: =+G31+G33 -> 172.88854 | H34: =+H31+H33 -> 187.80133 | I34: =+I31+I33 -> 201.5634 | L34: Año | M34: 2025 | N34: 2026 | O34: 2027 | P34: 2028 | Q34: 2029 | R34: 2030
L35: Depreciación | N35: =-(SUM(Datos!$E$23:$E$27)/5)/1000000 -> -53 | O35: =+N35 -> -53 | P35: =+O35 -> -53 | Q35: =+P35 -> -53 | R35: =+Q35 -> -53 | S35: Corregido
C36: Capex | D36: =-(SUM(Datos!E23:E27)+(Datos!E29*Supuestos!B$3)+(Datos!E28*Supuestos!B3))/1000000 -> -272.40356 | E36: 0 | F36: 0 | G36: 0 | H36: 0 | I36: 0 | J36: Corregido | L36: Intereses
C37: Flujo operativo | D37: =SUM(D34:D36) -> -272.40356 | E37: =+E34-E27 -> 36.611616 | F37: =+F34-F27 -> 191.67232 | G37: =+G34-G27 -> 225.88854 | H37: =+H34-H27 -> 240.80133 | I37: =+I34-I27 -> 254.5634 | L37: Activo Fijo | M37: =+D36 -> -272.40356 | N37: =+M37-E27 -> -219.40356 | O37: =+N37-F27 -> -166.40356 | P37: =+O37-G27 -> -113.40356 | Q37: =+P37-H27 -> -60.403559 | R37: =+Q37-I27 -> -7.4035594
C38: PAYBACK | D38: =+D37 -> -272.40356 | E38: =+E37+D38 -> -235.79194 | F38: =+F37+E38 -> -44.119624 | G38: =+G37+F38 -> 181.76892 | H38: =+H37+G38 -> 422.57024 | I38: =+I37+H38 -> 677.13365 | L38: Impuestos | N38: 0.27 | O38: 0.27 | P38: 0.27 | Q38: 0.27 | R38: 0.27
C39: PAYBACK años | D39: =+SUM(E39:I39) -> 3 | E39: =+IF(E38>0,E7,"") | F39: =+IF(F38>0,IF(E39="",F7,"-"),"") | G39: =+IF(G38>0,IF(F39="",G7,"-"),"") -> 3 | H39: =+IF(H38>0,IF(G39="",H7,"-"),"") -> - | I39: =+IF(I38>0,IF(H39="",I7,"-"),"") -> - | L39: extraido de la hoja "Control"
C40: Activos Netos Totales | E40: =+N37 -> -219.40356 | F40: =+O37 -> -166.40356 | G40: =+P37 -> -113.40356 | H40: =+Q37 -> -60.403559 | I40: =+R37 -> -7.4035594
C41: Capital de Trabajo | E41: =+N23/1000000 -> 100 | F41: =+O23/1000000 -> 100 | G41: =+P23/1000000 -> 100 | H41: =+Q23/1000000 -> 100 | I41: =+R23/1000000 -> 100
C42: Capital empleado | E42: =+SUM(E40:E41) -> -119.40356 | F42: =+SUM(F40:F41) -> -66.403559 | G42: =+SUM(G40:G41) -> -13.403559 | H42: =+SUM(H40:H41) -> 39.596441 | I42: =+SUM(I40:I41) -> 92.596441 | K42: =(Datos!E29*Supuestos!B$3)+(Datos!E28*Supuestos!B3) -> 7403559.4
C44: Rentabilidad | E44: =+E31/E10 -> -0.12472134 | F44: =+F31/F10 -> 0.19787717 | G44: =+G31/G10 -> 0.21929039 | H44: =+H31/H10 -> 0.2256685 | I44: =+I31/I10 -> 0.23067189
C46: Graficos

Sheet Supuestos
B1: 45925
B2: 2025 | C2: 2026 | D2: 2027 | E2: 2028 | F2: 2029 | G2: 2030
A3: UF | B3: 39485.65 | C3: =+B3*1.034 -> 40828.162 | D3: =+C3*1.034 -> 42216.32 | E3: =+D3*1.034 -> 43651.674 | F3: =+E3*1.034 -> 45135.831 | G3: =+F3*1.034 -> 46670.45

Sheet WACC Data
B2: Data Inputs
B4: WACC
B5: Country | C5: Country Risk Premium
B6: Argentina | C6: =C12 -> 0.1753273
B7: Chile | C7: 0.078897254
B8: Colombia | C8: 0.098361741
B9: Costa Rica | C9: 0.098436352
B10: Djbouti | C10: =C12 -> 0.1753273
B11: Ecuador | C11: 0.13434922
B12: Ethiopia | C12: 0.1753273
B13: Kenya | C13: 0.1134461
B14: Panama | C14: 0.082199788
B15: Peru | C15: 0.073876473
B16: Uruguay | C16: 0.086019882
